Workbook

Sheet Roster Detail
A1: Zava Retail Store Shift Roster (WFM export)
A2: Doc. No. HR-WFM-RS-2611 Version v3 As-of date 2026-11-03 Owner: Store Operations Scope: S031 for 11-04 to 11-08; S008 and S042 for 11-06 only
A4: Date | B4: Store Code | C4: Store Name | D4: Group | E4: Employee ID | F4: Tag | G4: Name | H4: Shift Code | I4: Start | J4: End | K4: Hours | L4: Attendance | M4: Remarks
A5: 46330 | B5: S031 | C5: Taipei Neihu | D5: Pickup Desk | E5: Z10231 | F5: A | G5: Mei-Ling Lee | H5: E1 | I5: 0.375 | J5: 0.70833333 | K5: =(J5-I5)*24 | L5: On site
A6: 46330 | B6: S031 | C6: Taipei Neihu | D6: Pickup Desk | E6: Z10232 | F6: B | G6: Chien-Hung Wang | H6: E2 | I6: 0.375 | J6: 0.75 | K6: =(J6-I6)*24 | L6: On site
A7: 46330 | B7: S031 | C7: Taipei Neihu | D7: Pickup Desk | E7: Z10233 | F7: C | G7: Chia-Ying Wu | H7: M3 | I7: 0.41666667 | J7: 0.79166667 | K7: =(J7-I7)*24 | L7: On site
A8: 46330 | B8: S031 | C8: Taipei Neihu | D8: Pickup Desk | E8: Z10234 | F8: D | G8: Chih-Wei Hsu | H8: M1 | I8: 0.41666667 | J8: 0.75 | K8: =(J8-I8)*24 | L8: On site
A9: 46330 | B9: S031 | C9: Taipei Neihu | D9: Pickup Desk | E9: Z10235 | F9: E | G9: Ya-Wen Cheng | H9: L2 | I9: 0.58333333 | J9: 0.91666667 | K9: =(J9-I9)*24 | L9: On site
A10: 46330 | B10: S031 | C10: Taipei Neihu | D10: Pickup Desk | E10: Z10236 | F10: F | G10: Tsung-Han Tsai | H10: L1 | I10: 0.54166667 | J10: 0.91666667 | K10: =(J10-I10)*24 | L10: On site
A11: 46330 | B11: S031 | C11: Taipei Neihu | D11: Sales Floor | E11: Z10237 | G11: Yi-An Lin | H11: E1 | I11: 0.375 | J11: 0.70833333 | K11: =(J11-I11)*24 | L11: On site
A12: 46330 | B12: S031 | C12: Taipei Neihu | D12: Sales Floor | E12: Z10238 | G12: Chun-Chieh Chang | H12: E1 | I12: 0.375 | J12: 0.70833333 | K12: =(J12-I12)*24 | L12: On site
A13: 46330 | B13: S031 | C13: Taipei Neihu | D13: Sales Floor | E13: Z10239 | G13: Kuan-Ting Liu | H13: M1 | I13: 0.41666667 | J13: 0.75 | K13: =(J13-I13)*24 | L13: On site
A14: 46330 | B14: S031 | C14: Taipei Neihu | D14: Checkout | E14: Z10240 | G14: Shu-Hua Yang | H14: M1 | I14: 0.41666667 | J14: 0.75 | K14: =(J14-I14)*24 | L14: On site
A15: 46330 | B15: S031 | C15: Taipei Neihu | D15: Checkout | E15: Z10241 | G15: Po-Han Huang | H15: L2 | I15: 0.58333333 | J15: 0.91666667 | K15: =(J15-I15)*24 | L15: On site
A16: 46330 | B16: S031 | C16: Taipei Neihu | D16: Back Office | E16: Z10242 | G16: Hsin-Yi Chou | H16: L2 | I16: 0.58333333 | J16: 0.91666667 | K16: =(J16-I16)*24 | L16: On site
A17: 46330 | B17: S031 | C17: Taipei Neihu | D17: Sales Floor | E17: Z10243 | G17: Shih-Han Tseng | H17: P1 | I17: 0.45833333 | J17: 0.75 | K17: =(J17-I17)*24 | L17: On site
A18: 46331 | B18: S031 | C18: Taipei Neihu | D18: Pickup Desk | E18: Z10231 | F18: A | G18: Mei-Ling Lee | H18: E2 | I18: 0.375 | J18: 0.75 | K18: =(J18-I18)*24 | L18: On site
A19: 46331 | B19: S031 | C19: Taipei Neihu | D19: Pickup Desk | E19: Z10232 | F19: B | G19: Chien-Hung Wang | H19: M1 | I19: 0.41666667 | J19: 0.75 | K19: =(J19-I19)*24 | L19: On site
A20: 46331 | B20: S031 | C20: Taipei Neihu | D20: Pickup Desk | E20: Z10233 | F20: C | G20: Chia-Ying Wu | H20: E1 | I20: 0.375 | J20: 0.70833333 | K20: =(J20-I20)*24 | L20: On site
A21: 46331 | B21: S031 | C21: Taipei Neihu | D21: Pickup Desk | E21: Z10234 | F21: D | G21: Chih-Wei Hsu | H21: E1 | I21: 0.375 | J21: 0.70833333 | K21: =(J21-I21)*24 | L21: On site
A22: 46331 | B22: S031 | C22: Taipei Neihu | D22: Pickup Desk | E22: Z10235 | F22: E | G22: Ya-Wen Cheng | H22: M3 | I22: 0.41666667 | J22: 0.79166667 | K22: =(J22-I22)*24 | L22: On site
A23: 46331 | B23: S031 | C23: Taipei Neihu | D23: Pickup Desk | E23: Z10236 | F23: F | G23: Tsung-Han Tsai | H23: L2 | I23: 0.58333333 | J23: 0.91666667 | K23: =(J23-I23)*24 | L23: On site
A24: 46331 | B24: S031 | C24: Taipei Neihu | D24: Sales Floor | E24: Z10237 | G24: Yi-An Lin | H24: E1 | I24: 0.375 | J24: 0.70833333 | K24: =(J24-I24)*24 | L24: On site
A25: 46331 | B25: S031 | C25: Taipei Neihu | D25: Sales Floor | E25: Z10238 | G25: Chun-Chieh Chang | H25: M1 | I25: 0.41666667 | J25: 0.75 | K25: =(J25-I25)*24 | L25: On site
A26: 46331 | B26: S031 | C26: Taipei Neihu | D26: Sales Floor | E26: Z10239 | G26: Kuan-Ting Liu | H26: M1 | I26: 0.41666667 | J26: 0.75 | K26: =(J26-I26)*24 | L26: On site
A27: 46331 | B27: S031 | C27: Taipei Neihu | D27: Checkout | E27: Z10240 | G27: Shu-Hua Yang | H27: E1 | I27: 0.375 | J27: 0.70833333 | K27: =(J27-I27)*24 | L27: On site
A28: 46331 | B28: S031 | C28: Taipei Neihu | D28: Checkout | E28: Z10241 | G28: Po-Han Huang | H28: L2 | I28: 0.58333333 | J28: 0.91666667 | K28: =(J28-I28)*24 | L28: On site
A29: 46331 | B29: S031 | C29: Taipei Neihu | D29: Back Office | E29: Z10242 | G29: Hsin-Yi Chou | H29: L2 | I29: 0.58333333 | J29: 0.91666667 | K29: =(J29-I29)*24 | L29: On site
A30: 46331 | B30: S031 | C30: Taipei Neihu | D30: Sales Floor | E30: Z10243 | G30: Shih-Han Tseng | H30: P1 | I30: 0.45833333 | J30: 0.75 | K30: =(J30-I30)*24 | L30: On site
A31: 46332 | B31: S031 | C31: Taipei Neihu | D31: Pickup Desk | E31: Z10231 | F31: A | G31: Mei-Ling Lee | H31: OFF | K31: 0 | L31: On leave (approved) | M31: Annual leave (HR ref. LV-26-1187)
A32: 46332 | B32: S031 | C32: Taipei Neihu | D32: Pickup Desk | E32: Z10232 | F32: B | G32: Chien-Hung Wang | H32: M2 | I32: 0.45833333 | J32: 0.70833333 | K32: =(J32-I32)*24 | L32: On site
A33: 46332 | B33: S031 | C33: Taipei Neihu | D33: Pickup Desk | E33: Z10233 | F33: C | G33: Chia-Ying Wu | H33: E2 | I33: 0.375 | J33: 0.75 | K33: =(J33-I33)*24 | L33: Loaned to other store | M33: Loaned to Xinzhuang for campaign prep (cross-store ref. XS-2611-014)
A34: 46332 | B34: S031 | C34: Taipei Neihu | D34: Pickup Desk | E34: Z10234 | F34: D | G34: Chih-Wei Hsu | H34: E1 | I34: 0.375 | J34: 0.70833333 | K34: =(J34-I34)*24 | L34: On site
A35: 46332 | B35: S031 | C35: Taipei Neihu | D35: Pickup Desk | E35: Z10235 | F35: E | G35: Ya-Wen Cheng | H35: M3 | I35: 0.41666667 | J35: 0.79166667 | K35: =(J35-I35)*24 | L35: On site
A36: 46332 | B36: S031 | C36: Taipei Neihu | D36: Pickup Desk | E36: Z10236 | F36: F | G36: Tsung-Han Tsai | H36: L1 | I36: 0.54166667 | J36: 0.91666667 | K36: =(J36-I36)*24 | L36: On site
A37: 46332 | B37: S031 | C37: Taipei Neihu | D37: Sales Floor | E37: Z10237 | G37: Yi-An Lin | H37: E1 | I37: 0.375 | J37: 0.70833333 | K37: =(J37-I37)*24 | L37: On site
A38: 46332 | B38: S031 | C38: Taipei Neihu | D38: Sales Floor | E38: Z10238 | G38: Chun-Chieh Chang | H38: E1 | I38: 0.375 | J38: 0.70833333 | K38: =(J38-I38)*24 | L38: On site
A39: 46332 | B39: S031 | C39: Taipei Neihu | D39: Sales Floor | E39: Z10239 | G39: Kuan-Ting Liu | H39: M1 | I39: 0.41666667 | J39: 0.75 | K39: =(J39-I39)*24 | L39: On site
A40: 46332 | B40: S031 | C40: Taipei Neihu | D40: Checkout | E40: Z10240 | G40: Shu-Hua Yang | H40: M1 | I40: 0.41666667 | J40: 0.75 | K40: =(J40-I40)*24 | L40: On site
A41: 46332 | B41: S031 | C41: Taipei Neihu | D41: Checkout | E41: Z10241 | G41: Po-Han Huang | H41: L2 | I41: 0.58333333 | J41: 0.91666667 | K41: =(J41-I41)*24 | L41: On site
...

Sheet Hours Summary
A1: S031 Daily Scheduled vs Required Hours
A2: Scheduled hours = SUMIFS over the Roster Detail sheet (all groups). Required hours come from labour demand model v2 (generated 2026-11-03).
A4: Date | B4: Store Code | C4: Scheduled (h) | D4: Required (h) | E4: Delta (h) | F4: Delta % | G4: Daily Cap (h)
A5: 46330 | B5: S031 | C5: =SUMIFS('Roster Detail'!$K:$K,'Roster Detail'!$A:$A,A5,'Roster Detail'!$B:$B,B5) | D5: 99 | E5: =C5-D5 | F5: =C5/D5-1 | G5: 10
A6: 46331 | B6: S031 | C6: =SUMIFS('Roster Detail'!$K:$K,'Roster Detail'!$A:$A,A6,'Roster Detail'!$B:$B,B6) | D6: 98 | E6: =C6-D6 | F6: =C6/D6-1 | G6: 10
A7: 46332 | B7: S031 | C7: =SUMIFS('Roster Detail'!$K:$K,'Roster Detail'!$A:$A,A7,'Roster Detail'!$B:$B,B7) | D7: 88 | E7: =C7-D7 | F7: =C7/D7-1 | G7: 10
A8: 46333 | B8: S031 | C8: =SUMIFS('Roster Detail'!$K:$K,'Roster Detail'!$A:$A,A8,'Roster Detail'!$B:$B,B8) | D8: 100 | E8: =C8-D8 | F8: =C8/D8-1 | G8: 10
A9: 46334 | B9: S031 | C9: =SUMIFS('Roster Detail'!$K:$K,'Roster Detail'!$A:$A,A9,'Roster Detail'!$B:$B,B9) | D9: 98 | E9: =C9-D9 | F9: =C9/D9-1 | G9: 10
A11: Note: the summary compares totals only, not hourly distribution.

Sheet Shift Codes
A1: Shift Code Table
A3: Code | B3: Name | C3: Start | D3: End | E3: Hours
A4: E1 | B4: Early | C4: 0.375 | D4: 0.70833333 | E4: =(D4-C4)*24
A5: E2 | B5: Early (long) | C5: 0.375 | D5: 0.75 | E5: =(D5-C5)*24
A6: M1 | B6: Mid | C6: 0.41666667 | D6: 0.75 | E6: =(D6-C6)*24
A7: M2 | B7: Mid (short) | C7: 0.45833333 | D7: 0.70833333 | E7: =(D7-C7)*24
A8: M3 | B8: Mid (long) | C8: 0.41666667 | D8: 0.79166667 | E8: =(D8-C8)*24
A9: L1 | B9: Late (long) | C9: 0.54166667 | D9: 0.91666667 | E9: =(D9-C9)*24
A10: L2 | B10: Late | C10: 0.58333333 | D10: 0.91666667 | E10: =(D10-C10)*24
A11: P1 | B11: Part-time | C11: 0.45833333 | D11: 0.75 | E11: =(D11-C11)*24
A12: OFF | B12: Day off | E12: 0

Sheet Change Log
A1: Roster Change Log
A3: Changed On | B3: Store Code | C3: Employee ID | D3: Change | E3: Status
A4: 46315 | B4: S031 | C4: Z10231 | D4: Annual leave request for 11-06 (full day) | E4: Approved
A5: 46319 | B5: S031 | C5: Z10241 | D5: 11-04 changed from L1 to L2 | E5: Closed
A6: 46322 | B6: S031 | C6: Z10233 | D6: Cross-store loan on 11-06 (XS-2611-014) | E6: Approved
A7: 46323 | B7: S031 | C7: Z10237 | D7: 11-08 shift swap (with H) | E7: Closed
A8: 46325 | B8: S008 | C8: Z20102 | D8: Overtime request for 11-06 | E8: Pending
A9: 46328 | B9: S042 | C9: Z20003 | D9: Sick leave 11-06 | E9: Closed
A10: 46329 | B10: S031 | C10: Z10243 | D10: Part-time hours updated | E10: Closed
